<?xml version="1.0" ?>
<!-- =================================================================================== -->
<!-- |    This document was autogenerated by xacro from /home/robot/inmoov_ros/src/inmoov_description/robots/inmoov.urdf.xacro | -->
<!-- |    EDITING THIS FILE BY HAND IS NOT RECOMMENDED                                 | -->
<!-- =================================================================================== -->
<robot name="inmoov" xmlns:xacro="http://ros.org/wiki/xacro">
  <!--xacro:property name="pi" value="3.1415926539"/-->
  <!--xacro:property name="pi" value="3.1415926539"/-->
  <!--xacro:property name="pi" value="3.1415926539"/-->
  <!--xacro:property name="pi" value="3.1415926539"/-->
  <!--xacro:property name="pi" value="3.1415926539"/-->
  <!--xacro:property name="pi" value="3.1415926539"/-->
  <!--xacro:property name="pi" value="3.1415926539"/-->
  <link name="base_link">
    <visual>
      <geometry>
        <cylinder length="0.11" radius="0.26" />
      </geometry>
      <origin rpy="0 0 0" xyz="0 0 0.055" />
      <material name="cbase">
        <color rgba="0.1 0.1 0.1 1" />
      </material>
    </visual>
  </link>
  <joint name="base_to_pedestal_link" type="fixed">
    <parent link="base_link" />
    <child link="pedestal_link" />
    <origin rpy="0 0 0" xyz="0 0 0" />
  </joint>
  <link name="pedestal_link">
    <visual>
      <geometry>
        <cylinder length="0.94" radius="0.0254" />
      </geometry>
      <origin rpy="0 0 0" xyz="0 0 0.58" />
      <material name="cbase">
        <color rgba="0.1 0.1 0.1 1" />
      </material>
    </visual>
  </link>
  <link name="head_tilt_link">
    <visual>
      <geometry>
        <mesh filename="package://inmoov_meshes/meshes/virtual.stl" scale="0.001 0.001 0.001" />
      </geometry>
      <origin rpy="0 0 3.1415" xyz="0 0 0" />
      <material name="cframe">
        <color rgba="0.40 0.40 0.40 1" />
      </material>
    </visual>
  </link>
  <joint name="pedestal_to_mid_stomach_joint" type="fixed">
    <parent link="pedestal_link" />
    <child link="mid_stomach_link" />
    <origin rpy="0 0 0" xyz="0 0 0" />
  </joint>
  <link name="mid_stomach_link">
    <visual>
      <geometry>
        <mesh filename="package://inmoov_meshes/meshes/mid_stomach.stl" scale="0.001 0.001 0.001" />
      </geometry>
      <origin rpy="0 0 0" xyz="0 0 1.152" />
      <material name="cframe">
        <color rgba="0.40 0.40 0.40 1" />
      </material>
    </visual>
  </link>
  <link name="disk_link">
    <visual>
      <geometry>
        <mesh filename="package://inmoov_meshes/meshes/disk.stl" scale="0.001 0.001 0.001" />
      </geometry>
      <origin rpy="0 0 0" xyz="0 0 0" />
      <material name="ccover">
        <color rgba="0.75 0.75 0.75 1.0" />
      </material>
    </visual>
  </link>
  <link name="top_stomach_link">
    <visual>
      <geometry>
        <mesh filename="package://inmoov_meshes/meshes/top_stomach.stl" scale="0.001 0.001 0.001" />
      </geometry>
      <origin rpy="0 0 0" xyz="0 0 0" />
      <material name="cframe">
        <color rgba="0.40 0.40 0.40 1" />
      </material>
    </visual>
  </link>
  <link name="torso_link">
    <visual>
      <geometry>
        <mesh filename="package://inmoov_meshes/meshes/torso.stl" scale="0.001 0.001 0.001" />
      </geometry>
      <origin rpy="0 0 0" xyz="0 0 0" />
      <material name="cframe">
        <color rgba="0.40 0.40 0.40 1" />
      </material>
    </visual>
  </link>
  <link name="kinect2_link">
    <visual>
      <geometry>
        <mesh filename="package://inmoov_meshes/meshes/kinectone.stl" scale="0.001 0.001 0.001" />
      </geometry>
      <origin rpy="1.57 0 0" xyz="0 0 0" />
      <material name="ckinect">
        <color rgba="0.1 0.1 0.1 1" />
      </material>
    </visual>
  </link>
  <link name="camera_link" />
  <link name="kinect2_ir_optical_frame">
    <visual>
      <geometry>
        <mesh filename="package://inmoov_meshes/meshes/kinectone.stl" scale="0.001 0.001 0.001" />
      </geometry>
      <origin rpy="1.57 0 0" xyz="0 0 0" />
      <material name="ckinect">
        <color rgba="0.1 0.1 0.1 1" />
      </material>
    </visual>
  </link>
  <!-- <link name="camera_ir_optical_frame">
    
  </link>

   <link name="camera_rgb_optical_frame">
    </link>-->
  <link name="kinect2_rgb_optical_frame">
    <visual>
      <geometry>
        <mesh filename="package://inmoov_meshes/meshes/kinectone.stl" scale="0.001 0.001 0.001" />
      </geometry>
      <origin rpy="1.57 0 0" xyz="0 0 0" />
      <material name="ckinect">
        <color rgba="0.1 0.1 0.1 1" />
      </material>
    </visual>
  </link>
  <link name="chestplate_link">
    <visual>
      <geometry>
        <mesh filename="package://inmoov_meshes/meshes/chest.stl" scale="0.001 0.001 0.001" />
      </geometry>
      <origin rpy="0 0 0" xyz="0 0 0" />
      <material name="ccover">
        <color rgba="0.75 0.75 0.75 1.0" />
      </material>
    </visual>
  </link>
  <joint name="waist_pan_joint" type="revolute">
    <axis xyz="0 0 1" />
    <limit effort="1000.0" lower="-0.453785605519" upper="0.453785605519" velocity="0.0" />
    <origin rpy="0 0 0" xyz="0 0 1.152" />
    <parent link="mid_stomach_link" />
    <child link="top_stomach_link" />
    <calibration rising="-4.60264" />
  </joint>
  <joint name="disk_joint" type="fixed">
    <origin rpy="0 0 0" xyz="0.046 0 0.09" />
    <parent link="top_stomach_link" />
    <child link="disk_link" />
  </joint>
  <joint name="waist_roll_joint" type="revolute">
    <axis xyz="1 0 0" />
    <limit effort="1000.0" lower="-0.261799387799" upper="0.261799387799" velocity="0.0" />
    <origin rpy="0 0 0" xyz="0 0 0.11" />
    <parent link="top_stomach_link" />
    <child link="torso_link" />
    <calibration rising="1.24602" />
  </joint>
  <joint name="chestplate_joint" type="fixed">
    <origin rpy="0 0 0" xyz="0.042 0 0.025" />
    <parent link="torso_link" />
    <child link="chestplate_link" />
  </joint>
  <joint name="kinect2_joint" type="fixed">
    <origin rpy="-1.57 0 -1.57" xyz="0 0 0.066" />
    <parent link="torso_link" />
    <child link="kinect2_link" />
  </joint>
  <joint name="camera_joint" type="fixed">
    <origin rpy="0.00000000 0.04558576 0.00000000" xyz="0.03000000 0.00000000 0.19210000" />
    <parent link="chestplate_link" />
    <child link="camera_link" />
  </joint>
  <joint name="kinect2_ir_optical_frame_joint" type="fixed">
    <origin rpy="-1.57 0 -1.57" xyz="0 0 0.066" />
    <parent link="torso_link" />
    <child link="kinect2_ir_optical_frame" />
  </joint>
  <!--<joint name="camera_ir_optical_frame_joint" type="fixed">
<origin rpy="-2.3553 0 -1.57" xyz="1 1 1"/>
    <parent link="camera_link"/>
    <child link="camera_ir_optical_frame"/>
  </joint>-->
  <joint name="kinect2_rgb_optical_joint" type="fixed">
    <origin rpy="-1.57 0 -1.57" xyz="0 0 0.066" />
    <parent link="torso_link" />
    <child link="kinect2_rgb_optical_frame" />
  </joint>
  <!-- <joint name="camera_rgb_optical_joint" type="fixed">
<origin rpy="-2.3553 0 -1.57" xyz=" 1 1 1"/>
    <parent link="camera_link"/>
    <child link="camera_rgb_optical_frame"/>
  </joint>-->
  <joint name="head_roll_joint" type="revolute">
    <axis xyz="1 0 0" />
    <limit effort="1000.0" lower="-0.349065850399" upper="0.349065850399" velocity="0.0" />
    <origin rpy="0 0 3.1415" xyz="-0.0315  -0.001 0.4551" />
    <parent link="torso_link" />
    <child link="head_tilt_link" />
  </joint>
  <joint name="head_tilt_joint" type="revolute">
    <axis xyz="0 1 0" />
    <limit effort="1000.0" lower="-0.261799387799" upper="0.296705972839" velocity="0.0" />
    <origin rpy="0 0 3.1415" xyz="0 0 0" />
    <parent link="head_tilt_link" />
    <child link="head_base_link" />
  </joint>
  <link name="head_base_link">
    <visual>
      <geometry>
        <mesh filename="package://inmoov_meshes/meshes/head_base.stl" scale="0.001 0.001 0.001" />
      </geometry>
      <origin rpy="0 0 0" xyz="0 0 0" />
      <material name="cframe">
        <color rgba="0.40 0.40 0.40 1" />
      </material>
    </visual>
  </link>
  <link name="head_link">
    <visual>
      <geometry>
        <mesh filename="package://inmoov_meshes/meshes/head.stl" scale="0.001 0.001 0.001" />
      </geometry>
      <origin rpy="0 0 0" xyz="0 0 0" />
      <material name="cframe">
        <color rgba="0.40 0.40 0.40 1" />
      </material>
    </visual>
  </link>
  <link name="jaw_link">
    <visual>
      <geometry>
        <mesh filename="package://inmoov_meshes/meshes/jaw.stl" scale="0.001 0.001 0.001" />
      </geometry>
      <origin rpy="0 0 0" xyz="0 0 0" />
      <material name="ccover">
        <color rgba="0.75 0.75 0.75 1.0" />
      </material>
    </visual>
  </link>
  <link name="skull_link">
    <visual>
      <geometry>
        <mesh filename="package://inmoov_meshes/meshes/skull.stl" scale="0.001 0.001 0.001" />
      </geometry>
      <origin rpy="0 0 0" xyz="0 0 0" />
      <material name="ccover">
        <color rgba="0.75 0.75 0.75 1.0" />
      </material>
    </visual>
  </link>
  <link name="left_ear_link">
    <visual>
      <geometry>
        <mesh filename="package://inmoov_meshes/meshes/earleftv1.stl" scale="0.001 0.001 0.001" />
      </geometry>
      <origin rpy="0 0 0" xyz="0 0 0" />
      <material name="cframe">
        <color rgba="0.40 0.40 0.40 1" />
      </material>
    </visual>
  </link>
  <link name="right_ear_link">
    <visual>
      <geometry>
        <mesh filename="package://inmoov_meshes/meshes/earrightv1.stl" scale="0.001 0.001 0.001" />
      </geometry>
      <origin rpy="0 0 0" xyz="0 0 0" />
      <material name="cframe">
        <color rgba="0.40 0.40 0.40 1" />
      </material>
    </visual>
  </link>
  <joint name="head_pan_joint" type="revolute">
    <axis xyz="0 0 1" />
    <limit effort="1000.0" lower="-1.4835298642" upper="1.4835298642" velocity="0.0" />
    <origin rpy="0 0 0" xyz="0 0 0.0245" />
    <parent link="head_base_link" />
    <child link="head_link" />
  </joint>
  <joint name="jaw_joint" type="revolute">
    <axis xyz="0 1 0" />
    <limit effort="1000.0" lower="0.0" upper="0.174532925199" velocity="0.0" />
    <origin rpy="0 0.09 0" xyz="0.0375 0.0005 0.0437" />
    <parent link="head_link" />
    <child link="jaw_link" />
  </joint>
  <joint name="skull_joint" type="fixed">
    <origin rpy="0 0 0" xyz="0.044 0 -0.0245" />
    <parent link="head_link" />
    <child link="skull_link" />
  </joint>
  <joint name="left_ear_joint" type="fixed">
    <origin rpy="0 0 0" xyz="0.035 0.056 0.0437" />
    <parent link="head_link" />
    <child link="left_ear_link" />
  </joint>
  <joint name="right_ear_joint" type="fixed">
    <origin rpy="0 0 0" xyz="0.035 -0.056 0.0437" />
    <parent link="head_link" />
    <child link="right_ear_link" />
  </joint>
  <link name="face_link">
    <visual>
      <geometry>
        <mesh filename="package://inmoov_meshes/meshes/face.stl" scale="0.001 0.001 0.001" />
      </geometry>
      <origin rpy="0 0 0" xyz="0 0 0" />
      <material name="ccover">
        <color rgba="0.75 0.75 0.75 1.0" />
      </material>
    </visual>
  </link>
  <joint name="eyes_tilt_joint" type="revolute">
    <axis xyz="0 1 0" />
    <limit effort="1000.0" lower="-0.523598775598" upper="0.261799387799" velocity="0.0" />
    <origin rpy="0 0 0" xyz="0 0 0" />
    <parent link="face_link" />
    <child link="eyesupport_link" />
  </joint>
  <link name="eyesupport_link">
    <visual>
      <geometry>
        <mesh filename="package://inmoov_meshes/meshes/eyesupport.stl" scale="0.001 0.001 0.001" />
      </geometry>
      <origin rpy="0 0 0" xyz="0 0 0" />
      <material name="cframe">
        <color rgba="0.40 0.40 0.40 1" />
      </material>
    </visual>
  </link>
  <link name="r_eyesupport_link">
    <visual>
      <geometry>
        <mesh filename="package://inmoov_meshes/meshes/r_eyesupport.stl" scale="0.001 0.001 0.001" />
      </geometry>
      <origin rpy="0 0 0" xyz="0 0 0" />
      <material name="cframe">
        <color rgba="0.40 0.40 0.40 1" />
      </material>
    </visual>
  </link>
  <link name="r_camera_link">
    <visual>
      <geometry>
        <mesh filename="package://inmoov_meshes/meshes/camera.stl" scale="0.001 0.001 0.001" />
      </geometry>
      <origin rpy="0 0 0" xyz="0 0 0" />
      <material name="ccamera">
        <color rgba="0.1 0.1 0.1 1" />
      </material>
    </visual>
  </link>
  <link name="r_eye_link">
    <visual>
      <geometry>
        <mesh filename="package://inmoov_meshes/meshes/eye.stl" scale="0.001 0.001 0.001" />
      </geometry>
      <origin rpy="0 0 0" xyz="0 0 0" />
      <material name="ceyeball">
        <color rgba="0.7 0.7 0.7 1" />
      </material>
    </visual>
  </link>
  <link name="r_iris_link">
    <visual>
      <geometry>
        <mesh filename="package://inmoov_meshes/meshes/iris.stl" scale="0.001 0.001 0.001" />
      </geometry>
      <origin rpy="0 0 0" xyz="0 0 0" />
      <material name="ciris">
        <color rgba="0.25 0.41 0.88 1" />
      </material>
    </visual>
  </link>
  <joint name="r_camera_joint" type="fixed">
    <origin rpy="0 0 0" xyz="-0.001 0 0" />
    <parent link="r_eyesupport_link" />
    <child link="r_camera_link" />
  </joint>
  <joint name="r_eye_joint" type="fixed">
    <origin rpy="0 0 0" xyz="0.003 0 0" />
    <parent link="r_eyesupport_link" />
    <child link="r_eye_link" />
  </joint>
  <joint name="r_iris_joint" type="fixed">
    <origin rpy="0 0 0" xyz="0.0061 0 0" />
    <parent link="r_eyesupport_link" />
    <child link="r_iris_link" />
  </joint>
  <joint name="eyes_pan_joint" type="revolute">
    <axis xyz="0 0 1" />
    <limit effort="1000.0" lower="-0.523598775598" upper="0.523598775598" velocity="0.0" />
    <origin rpy="0 0 0" xyz="0 0.033 -0.0036" />
    <parent link="eyesupport_link" />
    <child link="r_eyesupport_link" />
  </joint>
  <link name="l_eyesupport_link">
    <visual>
      <geometry>
        <mesh filename="package://inmoov_meshes/meshes/l_eyesupport.stl" scale="0.001 0.001 0.001" />
      </geometry>
      <origin rpy="0 0 0" xyz="0 0 0" />
      <material name="cframe">
        <color rgba="0.40 0.40 0.40 1" />
      </material>
    </visual>
  </link>
  <link name="l_camera_link">
    <visual>
      <geometry>
        <mesh filename="package://inmoov_meshes/meshes/camera.stl" scale="0.001 0.001 0.001" />
      </geometry>
      <origin rpy="0 0 0" xyz="0 0 0" />
      <material name="ccamera">
        <color rgba="0.1 0.1 0.1 1" />
      </material>
    </visual>
  </link>
  <link name="l_eye_link">
    <visual>
      <geometry>
        <mesh filename="package://inmoov_meshes/meshes/eye.stl" scale="0.001 0.001 0.001" />
      </geometry>
      <origin rpy="0 0 0" xyz="0 0 0" />
      <material name="ceyeball">
        <color rgba="0.7 0.7 0.7 1" />
      </material>
    </visual>
  </link>
  <link name="l_iris_link">
    <visual>
      <geometry>
        <mesh filename="package://inmoov_meshes/meshes/iris.stl" scale="0.001 0.001 0.001" />
      </geometry>
      <origin rpy="0 0 0" xyz="0 0 0" />
      <material name="ciris">
        <color rgba="0.25 0.41 0.88 1" />
      </material>
    </visual>
  </link>
  <joint name="l_camera_joint" type="fixed">
    <origin rpy="0 0 0" xyz="-0.001 0 0" />
    <parent link="l_eyesupport_link" />
    <child link="l_camera_link" />
  </joint>
  <joint name="l_eye_joint" type="fixed">
    <origin rpy="0 0 0" xyz="0.003 0 0" />
    <parent link="l_eyesupport_link" />
    <child link="l_eye_link" />
  </joint>
  <joint name="l_iris_joint" type="fixed">
    <origin rpy="0 0 0" xyz="0.0061 0 0" />
    <parent link="l_eyesupport_link" />
    <child link="l_iris_link" />
  </joint>
  <joint name="l_eye_pan_joint" type="revolute">
    <axis xyz="0 0 1" />
    <limit effort="1000.0" lower="-0.523598775598" upper="0.523598775598" velocity="0.0" />
    <mimic joint="eyes_pan_joint" multiplier="1" offset="0" />
    <origin rpy="0 0 0" xyz="0 -0.033 -0.0036" />
    <parent link="eyesupport_link" />
    <child link="l_eyesupport_link" />
  </joint>
  <joint name="face_joint" type="fixed">
    <origin rpy="0 0 0" xyz="0.0637 0 0.079" />
    <parent link="skull_link" />
    <child link="face_link" />
  </joint>
  <link name="r_shoulder_base_link">
    <visual>
      <geometry>
        <mesh filename="package://inmoov_meshes/meshes/r_shoulder_base.stl" scale="0.001 0.001 0.001" />
      </geometry>
      <origin rpy="0 0 0" xyz="0 0 0" />
      <material name="cframe">
        <color rgba="0.40 0.40 0.40 1" />
      </material>
    </visual>
  </link>
  <link name="r_shoulder_link">
    <visual>
      <geometry>
        <mesh filename="package://inmoov_meshes/meshes/r_shoulder.stl" scale="0.001 0.001 0.001" />
      </geometry>
      <origin rpy="0 0 0" xyz="0 0 0" />
      <material name="cframe">
        <color rgba="0.40 0.40 0.40 1" />
      </material>
    </visual>
  </link>
  <link name="r_bicep_link">
    <visual>
      <geometry>
        <mesh filename="package://inmoov_meshes/meshes/bicep.stl" scale="0.001 0.001 0.001" />
      </geometry>
      <origin rpy="0 0 0" xyz="0 0 0" />
      <material name="cframe">
        <color rgba="0.40 0.40 0.40 1" />
      </material>
    </visual>
  </link>
  <!--<link name="${side}_bicepcover_link">
    <visual>
      <geometry>
        <mesh filename="package://inmoov_meshes/meshes/bicepcover.stl" scale="0.001 0.001 0.001"/>
      </geometry>
      <origin rpy="0 0 0" xyz="0 0 0"/>
      <xacro:cover_color/>
    </visual>
  </link>-->
  <link name="r_forearm_link">
    <visual>
      <geometry>
        <mesh filename="package://inmoov_meshes/meshes/r_forearm.stl" scale="0.001 0.001 0.001" />
      </geometry>
      <origin rpy="0 0 0" xyz="0.001 0 0" />
      <material name="ccover">
        <color rgba="0.75 0.75 0.75 1.0" />
      </material>
    </visual>
  </link>
  <joint name="r_shoulder_lift_joint" type="revolute">
    <axis xyz="0 1 0" />
    <limit effort="1000.0" lower="-3.12413936107" upper="0.267035375555" velocity="0.0" />
    <origin rpy="0 0 0" xyz="0 -0.012 -0.04" />
    <parent link="r_shoulder_base_link" />
    <child link="r_shoulder_link" />
    <calibration rising="-4.85127" />
  </joint>
  <joint name="r_upper_arm_roll_joint" type="revolute">
    <axis xyz="0 0 1" />
    <limit effort="1000.0" lower="-0.925024503557" upper="1.0471975512" velocity="0.0" />
    <origin rpy="0 0 0" xyz="0 -0.066 -0.060" />
    <parent link="r_shoulder_link" />
    <child link="r_bicep_link" />
    <calibration rising="-2.91532" />
  </joint>
  <joint name="r_elbow_flex_joint" type="revolute">
    <axis xyz="0 1 0" />
    <limit effort="1000.0" lower="-1.3962634016" upper="-0.218166156499" velocity="0.0" />
    <origin rpy="0 0 0" xyz="-0.0278 0 -0.2235" />
    <parent link="r_bicep_link" />
    <child link="r_forearm_link" />
    <calibration rising="-0.964627" />
  </joint>
  <!--<joint name="${side}_bicepcover_joint" type="fixed">
    <origin rpy="0 0 0" xyz="0 0 0"/>
    <parent link="${side}_bicep_link"/>
    <child link="${side}_bicepcover_link"/>
  </joint>-->
  <joint name="r_shoulder_out_joint" type="revolute">
    <axis xyz="1 0 0" />
    <limit effort="1000.0" lower="-1.0471975512" upper="-0.12217304764" velocity="0.0" />
    <origin rpy="0 0 0" xyz="0 -0.143 0.298" />
    <parent link="torso_link" />
    <child link="r_shoulder_base_link" />
    <calibration rising="-1.68716" />
  </joint>
  <link name="r_hand_link">
    <visual>
      <geometry>
        <mesh filename="package://inmoov_meshes/meshes/r_hand.stl" scale="0.001 0.001 0.001" />
      </geometry>
      <origin rpy="0 0 0" xyz="0 0 0" />
      <material name="cframe">
        <color rgba="0.40 0.40 0.40 1" />
      </material>
    </visual>
  </link>
  <link name="r_thumb1_link">
    <visual>
      <geometry>
        <mesh filename="package://inmoov_meshes/meshes/r_thumb5_1.stl" scale="0.001 0.001 0.001" />
      </geometry>
      <origin rpy="0 0 0" xyz="0 0 0" />
      <material name="cframe">
        <color rgba="0.40 0.40 0.40 1" />
      </material>
    </visual>
  </link>
  <link name="r_thumb2_link">
    <visual>
      <geometry>
        <mesh filename="package://inmoov_meshes/meshes/thumb5_2.stl" scale="0.001 0.001 0.001" />
      </geometry>
      <origin rpy="0 0 0" xyz="0 0 0" />
      <material name="cframe">
        <color rgba="0.40 0.40 0.40 1" />
      </material>
    </visual>
  </link>
  <link name="r_thumb3_link">
    <visual>
      <geometry>
        <mesh filename="package://inmoov_meshes/meshes/thumb5_3.stl" scale="0.001 0.001 0.001" />
      </geometry>
      <origin rpy="0 0 0" xyz="0 0 0" />
      <material name="cframe">
        <color rgba="0.40 0.40 0.40 1" />
      </material>
    </visual>
  </link>
  <link name="r_index1_link">
    <visual>
      <geometry>
        <mesh filename="package://inmoov_meshes/meshes/index3_1.stl" scale="0.001 0.001 0.001" />
      </geometry>
      <origin rpy="0 0 0" xyz="0 0 0" />
      <material name="cframe">
        <color rgba="0.40 0.40 0.40 1" />
      </material>
    </visual>
  </link>
  <link name="r_index2_link">
    <visual>
      <geometry>
        <mesh filename="package://inmoov_meshes/meshes/index3_2.stl" scale="0.001 0.001 0.001" />
      </geometry>
      <origin rpy="0 0 0" xyz="0 0 0" />
      <material name="cframe">
        <color rgba="0.40 0.40 0.40 1" />
      </material>
    </visual>
  </link>
  <link name="r_index3_link">
    <visual>
      <geometry>
        <mesh filename="package://inmoov_meshes/meshes/index3_3.stl" scale="0.001 0.001 0.001" />
      </geometry>
      <origin rpy="0 0 0" xyz="0 0 0" />
      <material name="cframe">
        <color rgba="0.40 0.40 0.40 1" />
      </material>
    </visual>
  </link>
  <link name="r_middle1_link">
    <visual>
      <geometry>
        <mesh filename="package://inmoov_meshes/meshes/middle3_1.stl" scale="0.001 0.001 0.001" />
      </geometry>
      <origin rpy="0 0 0" xyz="0 0 0" />
      <material name="cframe">
        <color rgba="0.40 0.40 0.40 1" />
      </material>
    </visual>
  </link>
  <link name="r_middle2_link">
    <visual>
      <geometry>
        <mesh filename="package://inmoov_meshes/meshes/middle3_2.stl" scale="0.001 0.001 0.001" />
      </geometry>
      <origin rpy="0 0 0" xyz="0 0 0" />
      <material name="cframe">
        <color rgba="0.40 0.40 0.40 1" />
      </material>
    </visual>
  </link>
  <link name="r_middle3_link">
    <visual>
      <geometry>
        <mesh filename="package://inmoov_meshes/meshes/middle3_3.stl" scale="0.001 0.001 0.001" />
      </geometry>
      <origin rpy="0 0 0" xyz="0 0 0" />
      <material name="cframe">
        <color rgba="0.40 0.40 0.40 1" />
      </material>
    </visual>
  </link>
  <link name="r_ring1_link">
    <visual>
      <geometry>
        <mesh filename="package://inmoov_meshes/meshes/r_ring3_1.stl" scale="0.001 0.001 0.001" />
      </geometry>
      <origin rpy="0 0 0" xyz="0 0 0" />
      <material name="cframe">
        <color rgba="0.40 0.40 0.40 1" />
      </material>
    </visual>
  </link>
  <link name="r_ring2_link">
    <visual>
      <geometry>
        <mesh filename="package://inmoov_meshes/meshes/ring3_2.stl" scale="0.001 0.001 0.001" />
      </geometry>
      <origin rpy="0 0 0" xyz="0 0 0" />
      <material name="cframe">
        <color rgba="0.40 0.40 0.40 1" />
      </material>
    </visual>
  </link>
  <link name="r_ring3_link">
    <visual>
      <geometry>
        <mesh filename="package://inmoov_meshes/meshes/ring3_3.stl" scale="0.001 0.001 0.001" />
      </geometry>
      <origin rpy="0 0 0" xyz="0 0 0" />
      <material name="cframe">
        <color rgba="0.40 0.40 0.40 1" />
      </material>
    </visual>
  </link>
  <link name="r_ring4_link">
    <visual>
      <geometry>
        <mesh filename="package://inmoov_meshes/meshes/ring3_4.stl" scale="0.001 0.001 0.001" />
      </geometry>
      <origin rpy="0 0 0" xyz="0 0 0" />
      <material name="cframe">
        <color rgba="0.40 0.40 0.40 1" />
      </material>
    </visual>
  </link>
  <link name="r_pinky1_link">
    <visual>
      <geometry>
        <mesh filename="package://inmoov_meshes/meshes/r_pinky3_1.stl" scale="0.001 0.001 0.001" />
      </geometry>
      <origin rpy="0 0 0" xyz="0 0 0" />
      <material name="cframe">
        <color rgba="0.40 0.40 0.40 1" />
      </material>
    </visual>
  </link>
  <link name="r_pinky2_link">
    <visual>
      <geometry>
        <mesh filename="package://inmoov_meshes/meshes/pinky3_2.stl" scale="0.001 0.001 0.001" />
      </geometry>
      <origin rpy="0 0 0" xyz="0 0 0" />
      <material name="cframe">
        <color rgba="0.40 0.40 0.40 1" />
      </material>
    </visual>
  </link>
  <link name="r_pinky3_link">
    <visual>
      <geometry>
        <mesh filename="package://inmoov_meshes/meshes/pinky3_3.stl" scale="0.001 0.001 0.001" />
      </geometry>
      <origin rpy="0 0 0" xyz="0 0 0" />
      <material name="cframe">
        <color rgba="0.40 0.40 0.40 1" />
      </material>
    </visual>
  </link>
  <link name="r_pinky4_link">
    <visual>
      <geometry>
        <mesh filename="package://inmoov_meshes/meshes/pinky3_4.stl" scale="0.001 0.001 0.001" />
      </geometry>
      <origin rpy="0 0 0" xyz="0 0 0" />
      <material name="cframe">
        <color rgba="0.40 0.40 0.40 1" />
      </material>
    </visual>
  </link>
  <link name="r_gripper_link" />
  <joint name="r_gripper_joint" type="fixed">
    <origin rpy="1.57 0 3.14" xyz="-0.0127 0 -0.0762" />
    <parent link="r_hand_link" />
    <child link="r_gripper_link" />
  </joint>
  <joint name="r_thumb1_joint" type="revolute">
    <axis xyz="0 0 1" />
    <limit effort="1000.0" lower="0.0" upper="1.0471975512" velocity="0.0" />
    <origin rpy="0.1 0 0" xyz="0 0.029 -0.0577" />
    <mimic joint="r_thumb_joint" multiplier="0.75" offset="0" />
    <parent link="r_hand_link" />
    <child link="r_thumb1_link" />
  </joint>
  <joint name="r_thumb_joint" type="revolute">
    <axis xyz="0 1 0" />
    <limit effort="1000.0" lower="0.0" upper="1.0471975512" velocity="0.0" />
    <origin rpy="0.825 -0.1 0.3" xyz="-0.00052 0.02725  -0.013" />
    <parent link="r_thumb1_link" />
    <child link="r_thumb2_link" />
  </joint>
  <joint name="r_thumb3_joint" type="revolute">
    <axis xyz="0 1 0" />
    <limit effort="1000.0" lower="0.0" upper="1.0471975512" velocity="0.0" />
    <origin rpy="0 0 0" xyz="0 0 -0.035" />
    <mimic joint="r_thumb_joint" multiplier="1" offset="0" />
    <parent link="r_thumb2_link" />
    <child link="r_thumb3_link" />
  </joint>
  <joint name="r_index1_joint" type="revolute">
    <axis xyz="0 1 0" />
    <limit effort="1000.0" lower="0.0" upper="1.4835298642" velocity="0.0" />
    <origin rpy="0.1 0 0" xyz="-0.0015 0.0342  -0.119" />
    <mimic joint="r_index_joint" multiplier="1" offset="0" />
    <parent link="r_hand_link" />
    <child link="r_index1_link" />
  </joint>
  <joint name="r_index_joint" type="revolute">
    <axis xyz="0 1 0" />
    <limit effort="1000.0" lower="0.0" upper="1.4835298642" velocity="0.0" />
    <origin rpy="0 0 0" xyz="0 0.001 -0.03595" />
    <parent link="r_index1_link" />
    <child link="r_index2_link" />
  </joint>
  <joint name="r_index3_joint" type="revolute">
    <axis xyz="0 1 0" />
    <limit effort="1000.0" lower="0.0" upper="1.4835298642" velocity="0.0" />
    <origin rpy="0 0 0" xyz="0 0 -0.024" />
    <mimic joint="r_index_joint" multiplier="1" offset="0" />
    <parent link="r_index2_link" />
    <child link="r_index3_link" />
  </joint>
  <joint name="r_middle1_joint" type="revolute">
    <axis xyz="0 1 0" />
    <limit effort="1000.0" lower="0.0" upper="1.4835298642" velocity="0.0" />
    <origin rpy="0 0 0" xyz="-0.00175 0.007  -0.12325" />
    <mimic joint="r_middle_joint" multiplier="1" offset="0" />
    <parent link="r_hand_link" />
    <child link="r_middle1_link" />
  </joint>
  <joint name="r_middle_joint" type="revolute">
    <axis xyz="0 1 0" />
    <limit effort="1000.0" lower="0.0" upper="1.4835298642" velocity="0.0" />
    <origin rpy="0 0 0" xyz="0 0.000 -0.0389" />
    <parent link="r_middle1_link" />
    <child link="r_middle2_link" />
  </joint>
  <joint name="r_middle3_joint" type="revolute">
    <axis xyz="0 1 0" />
    <limit effort="1000.0" lower="0.0" upper="1.4835298642" velocity="0.0" />
    <origin rpy="0 0 0" xyz="0 0.0005 -0.0259" />
    <mimic joint="r_middle_joint" multiplier="1" offset="0" />
    <parent link="r_middle2_link" />
    <child link="r_middle3_link" />
  </joint>
  <joint name="r_ring1_joint" type="revolute">
    <axis xyz="0 0 1" />
    <limit effort="1000.0" lower="0.0" upper="1.308996939" velocity="0.0" />
    <origin rpy="0.7 0 0" xyz="0 -0.00705 -0.0794" />
    <mimic joint="r_ring_joint" multiplier="-0.1" offset="0" />
    <parent link="r_hand_link" />
    <child link="r_ring1_link" />
  </joint>
  <joint name="r_ring_joint" type="revolute">
    <axis xyz="0 1 0" />
    <limit effort="1000.0" lower="0.0" upper="1.308996939" velocity="0.0" />
    <origin rpy="-0.7775 0 0" xyz="0.00126 -0.0351 -0.0166" />
    <parent link="r_ring1_link" />
    <child link="r_ring2_link" />
  </joint>
  <joint name="r_ring3_joint" type="revolute">
    <axis xyz="0 1 0" />
    <limit effort="1000.0" lower="0.0" upper="1.308996939" velocity="0.0" />
    <origin rpy="0 0 0" xyz="0 0.0005 -0.0345" />
    <mimic joint="r_ring_joint" multiplier="1" offset="0" />
    <parent link="r_ring2_link" />
    <child link="r_ring3_link" />
  </joint>
  <joint name="r_ring4_joint" type="revolute">
    <axis xyz="0 1 0" />
    <limit effort="1000.0" lower="0.0" upper="1.308996939" velocity="0.0" />
    <origin rpy="0 0 0" xyz="0 0.0004 -0.0229" />
    <mimic joint="r_ring_joint" multiplier="1" offset="0" />
    <parent link="r_ring3_link" />
    <child link="r_ring4_link" />
  </joint>
  <joint name="r_pinky1_joint" type="revolute">
    <axis xyz="0 0 1" />
    <limit effort="1000.0" lower="0.0" upper="1.308996939" velocity="0.0" />
    <origin rpy="0.7 0 0" xyz="0 -0.027 -0.0555" />
    <mimic joint="r_pinky_joint" multiplier="-0.1" offset="0" />
    <parent link="r_hand_link" />
    <child link="r_pinky1_link" />
  </joint>
  <joint name="r_pinky_joint" type="revolute">
    <axis xyz="0 1 0" />
    <limit effort="1000.0" lower="0.0" upper="1.308996939" velocity="0.0" />
    <origin rpy="-0.93 0 0" xyz="0 -0.046 -0.0228" />
    <parent link="r_pinky1_link" />
    <child link="r_pinky2_link" />
  </joint>
  <joint name="r_pinky3_joint" type="revolute">
    <axis xyz="0 1 0" />
    <limit effort="1000.0" lower="0.0" upper="1.308996939" velocity="0.0" />
    <origin rpy="0 0 0" xyz="0 0.0005 -0.031" />
    <mimic joint="r_pinky_joint" multiplier="1" offset="0" />
    <parent link="r_pinky2_link" />
    <child link="r_pinky3_link" />
  </joint>
  <joint name="r_pinky4_joint" type="revolute">
    <axis xyz="0 1 0" />
    <limit effort="1000.0" lower="0.0" upper="1.308996939" velocity="0.0" />
    <origin rpy="0 0 0" xyz="0 0.0004 -0.0208" />
    <mimic joint="r_pinky_joint" multiplier="1" offset="0" />
    <parent link="r_pinky3_link" />
    <child link="r_pinky4_link" />
  </joint>
  <link name="r_handcover_link">
    <visual>
      <geometry>
        <mesh filename="package://inmoov_meshes/meshes/r_cover_hand.stl" scale="0.001 0.001 0.001" />
      </geometry>
      <origin rpy="0 0 0" xyz="0 0 0" />
      <material name="ccover">
        <color rgba="0.75 0.75 0.75 1.0" />
      </material>
    </visual>
  </link>
  <link name="r_cover_handring_link">
    <visual>
      <geometry>
        <mesh filename="package://inmoov_meshes/meshes/r_cover_handring.stl" scale="0.001 0.001 0.001" />
      </geometry>
      <origin rpy="0 0 0" xyz="0 0 0" />
      <material name="ccover">
        <color rgba="0.75 0.75 0.75 1.0" />
      </material>
    </visual>
  </link>
  <link name="r_cover_handpinky_link">
    <visual>
      <geometry>
        <mesh filename="package://inmoov_meshes/meshes/r_cover_handpinky.stl" scale="0.001 0.001 0.001" />
      </geometry>
      <origin rpy="0 0 0" xyz="0 0 0" />
      <material name="ccover">
        <color rgba="0.75 0.75 0.75 1.0" />
      </material>
    </visual>
  </link>
  <link name="r_cover_thumb_link">
    <visual>
      <geometry>
        <mesh filename="package://inmoov_meshes/meshes/r_cover_thumb.stl" scale="0.001 0.001 0.001" />
      </geometry>
      <origin rpy="0 0 0" xyz="0 0 0" />
      <material name="ccover">
        <color rgba="0.75 0.75 0.75 1.0" />
      </material>
    </visual>
  </link>
  <link name="r_cover_index_link">
    <visual>
      <geometry>
        <mesh filename="package://inmoov_meshes/meshes/r_cover_index.stl" scale="0.001 0.001 0.001" />
      </geometry>
      <origin rpy="0 0 0" xyz="0 0 0" />
      <material name="ccover">
        <color rgba="0.75 0.75 0.75 1.0" />
      </material>
    </visual>
  </link>
  <link name="r_cover_middle_link">
    <visual>
      <geometry>
        <mesh filename="package://inmoov_meshes/meshes/r_cover_middle.stl" scale="0.001 0.001 0.001" />
      </geometry>
      <origin rpy="0 0 0" xyz="0 0 0" />
      <material name="ccover">
        <color rgba="0.75 0.75 0.75 1.0" />
      </material>
    </visual>
  </link>
  <link name="r_cover_ring_link">
    <visual>
      <geometry>
        <mesh filename="package://inmoov_meshes/meshes/r_cover_ring.stl" scale="0.001 0.001 0.001" />
      </geometry>
      <origin rpy="0 0 0" xyz="0 0 0" />
      <material name="ccover">
        <color rgba="0.75 0.75 0.75 1.0" />
      </material>
    </visual>
  </link>
  <link name="r_cover_pinky_link">
    <visual>
      <geometry>
        <mesh filename="package://inmoov_meshes/meshes/r_cover_pinky.stl" scale="0.001 0.001 0.001" />
      </geometry>
      <origin rpy="0 0 0" xyz="0 0 0" />
      <material name="ccover">
        <color rgba="0.75 0.75 0.75 1.0" />
      </material>
    </visual>
  </link>
  <joint name="r_handcover_joint" type="fixed">
    <origin rpy="0 0 0" xyz="0.009 0.0192 -0.0977" />
    <parent link="r_hand_link" />
    <child link="r_handcover_link" />
  </joint>
  <joint name="r_cover_handpinky_joint" type="fixed">
    <origin rpy="-0.7 0 0" xyz="0.01 -0.02025 -0.0071" />
    <parent link="r_pinky1_link" />
    <child link="r_cover_handpinky_link" />
  </joint>
  <joint name="r_cover_handring_joint" type="fixed">
    <origin rpy="-0.7 0 0" xyz="0.009 -0.015 -0.0008" />
    <parent link="r_ring1_link" />
    <child link="r_cover_handring_link" />
  </joint>
  <joint name="r_cover_middle_joint" type="fixed">
    <origin rpy="0 -0.05 0" xyz="0.0071 0 -0.012" />
    <parent link="r_middle1_link" />
    <child link="r_cover_middle_link" />
  </joint>
  <joint name="r_cover_thumb_joint" type="fixed">
    <origin rpy="0.05 0 0" xyz="0.01 0.02125 0.0047" />
    <parent link="r_thumb1_link" />
    <child link="r_cover_thumb_link" />
  </joint>
  <joint name="r_cover_index_joint" type="fixed">
    <origin rpy="0 0.05 0" xyz="0.0071 0 -0.012" />
    <parent link="r_index1_link" />
    <child link="r_cover_index_link" />
  </joint>
  <joint name="r_cover_ring_joint" type="fixed">
    <origin rpy="0.1 -0.05 0" xyz="0.005 0 -0.011" />
    <parent link="r_ring2_link" />
    <child link="r_cover_ring_link" />
  </joint>
  <joint name="r_cover_pinky_joint" type="fixed">
    <origin rpy="0.1 -0.05 0" xyz="0.005 0 -0.0105" />
    <parent link="r_pinky2_link" />
    <child link="r_cover_pinky_link" />
  </joint>
  <joint name="r_wrist_roll_joint" type="revolute">
    <axis xyz="0 0 1" />
    <limit effort="1000.0" lower="2.18166156499" upper="3.92699081699" velocity="0.0" />
    <origin rpy="0 0 1.57" xyz="-0.0144 0.01  -0.2885" />
    <parent link="r_forearm_link" />
    <child link="r_hand_link" />
    <calibration rising="4.55686" />
  </joint>
  <link name="l_shoulder_base_link">
    <visual>
      <geometry>
        <mesh filename="package://inmoov_meshes/meshes/l_shoulder_base.stl" scale="0.001 0.001 0.001" />
      </geometry>
      <origin rpy="0 0 0" xyz="0 0 0" />
      <material name="cframe">
        <color rgba="0.40 0.40 0.40 1" />
      </material>
    </visual>
  </link>
  <link name="l_shoulder_link">
    <visual>
      <geometry>
        <mesh filename="package://inmoov_meshes/meshes/l_shoulder.stl" scale="0.001 0.001 0.001" />
      </geometry>
      <origin rpy="0 0 0" xyz="0 0 0" />
      <material name="cframe">
        <color rgba="0.40 0.40 0.40 1" />
      </material>
    </visual>
  </link>
  <link name="l_bicep_link">
    <visual>
      <geometry>
        <mesh filename="package://inmoov_meshes/meshes/bicep.stl" scale="0.001 0.001 0.001" />
      </geometry>
      <origin rpy="0 0 0" xyz="0 0 0" />
      <material name="cframe">
        <color rgba="0.40 0.40 0.40 1" />
      </material>
    </visual>
  </link>
  <!--<link name="${side}_bicepcover_link">
    <visual>
      <geometry>
        <mesh filename="package://inmoov_meshes/meshes/bicepcover.stl" scale="0.001 0.001 0.001"/>
      </geometry>
      <origin rpy="0 0 0" xyz="0 0 0"/>
      <xacro:cover_color/>
    </visual>
  </link>-->
  <link name="l_forearm_link">
    <visual>
      <geometry>
        <mesh filename="package://inmoov_meshes/meshes/l_forearm.stl" scale="0.001 0.001 0.001" />
      </geometry>
      <origin rpy="0 0 0" xyz="-0.001 0 0" />
      <material name="ccover">
        <color rgba="0.75 0.75 0.75 1.0" />
      </material>
    </visual>
  </link>
  <joint name="l_shoulder_lift_joint" type="revolute">
    <axis xyz="0 1 0" />
    <limit effort="1000.0" lower="-3.14159265359" upper="0.541052068118" velocity="0.0" />
    <origin rpy="0 0 0" xyz="0 0.012 -0.04" />
    <parent link="l_shoulder_base_link" />
    <child link="l_shoulder_link" />
  </joint>
  <joint name="l_upper_arm_roll_joint" type="revolute">
    <axis xyz="0 0 1" />
    <limit effort="1000.0" lower="-1.53588974176" upper="1.44862327916" velocity="0.0" />
    <origin rpy="0 0 0" xyz="0 0.066 -0.060" />
    <parent link="l_shoulder_link" />
    <child link="l_bicep_link" />
  </joint>
  <joint name="l_elbow_flex_joint" type="revolute">
    <axis xyz="0 1 0" />
    <limit effort="1000.0" lower="-1.4835298642" upper="-0.383972435439" velocity="0.0" />
    <origin rpy="0 0 0" xyz="-0.0278 0 -0.2235" />
    <parent link="l_bicep_link" />
    <child link="l_forearm_link" />
  </joint>
  <!--<joint name="${side}_bicepcover_joint" type="fixed">
    <origin rpy="0 0 0" xyz="0 0 0"/>
    <parent link="${side}_bicep_link"/>
    <child link="${side}_bicepcover_link"/>
  </joint>-->
  <joint name="l_shoulder_out_joint" type="revolute">
    <axis xyz="1 0 0" />
    <limit effort="1000.0" lower="0.0872664625997" upper="1.27409035396" velocity="0.0" />
    <origin rpy="0 0 0" xyz="0 0.143 0.298" />
    <parent link="torso_link" />
    <child link="l_shoulder_base_link" />
  </joint>
  <link name="l_hand_link">
    <visual>
      <geometry>
        <mesh filename="package://inmoov_meshes/meshes/l_hand.stl" scale="0.001 0.001 0.001" />
      </geometry>
      <origin rpy="0 0 0" xyz="0 0 0" />
      <material name="cframe">
        <color rgba="0.40 0.40 0.40 1" />
      </material>
    </visual>
  </link>
  <link name="l_thumb1_link">
    <visual>
      <geometry>
        <mesh filename="package://inmoov_meshes/meshes/l_thumb5_1.stl" scale="0.001 0.001 0.001" />
      </geometry>
      <origin rpy="0 0 0" xyz="0 0 0" />
      <material name="cframe">
        <color rgba="0.40 0.40 0.40 1" />
      </material>
    </visual>
  </link>
  <link name="l_thumb2_link">
    <visual>
      <geometry>
        <mesh filename="package://inmoov_meshes/meshes/thumb5_2.stl" scale="0.001 0.001 0.001" />
      </geometry>
      <origin rpy="0 0 0" xyz="0 0 0" />
      <material name="cframe">
        <color rgba="0.40 0.40 0.40 1" />
      </material>
    </visual>
  </link>
  <link name="l_thumb3_link">
    <visual>
      <geometry>
        <mesh filename="package://inmoov_meshes/meshes/thumb5_3.stl" scale="0.001 0.001 0.001" />
      </geometry>
      <origin rpy="0 0 0" xyz="0 0 0" />
      <material name="cframe">
        <color rgba="0.40 0.40 0.40 1" />
      </material>
    </visual>
  </link>
  <link name="l_index1_link">
    <visual>
      <geometry>
        <mesh filename="package://inmoov_meshes/meshes/index3_1.stl" scale="0.001 0.001 0.001" />
      </geometry>
      <origin rpy="0 0 0" xyz="0 0 0" />
      <material name="cframe">
        <color rgba="0.40 0.40 0.40 1" />
      </material>
    </visual>
  </link>
  <link name="l_index2_link">
    <visual>
      <geometry>
        <mesh filename="package://inmoov_meshes/meshes/index3_2.stl" scale="0.001 0.001 0.001" />
      </geometry>
      <origin rpy="0 0 0" xyz="0 0 0" />
      <material name="cframe">
        <color rgba="0.40 0.40 0.40 1" />
      </material>
    </visual>
  </link>
  <link name="l_index3_link">
    <visual>
      <geometry>
        <mesh filename="package://inmoov_meshes/meshes/index3_3.stl" scale="0.001 0.001 0.001" />
      </geometry>
      <origin rpy="0 0 0" xyz="0 0 0" />
      <material name="cframe">
        <color rgba="0.40 0.40 0.40 1" />
      </material>
    </visual>
  </link>
  <link name="l_middle1_link">
    <visual>
      <geometry>
        <mesh filename="package://inmoov_meshes/meshes/middle3_1.stl" scale="0.001 0.001 0.001" />
      </geometry>
      <origin rpy="0 0 0" xyz="0 0 0" />
      <material name="cframe">
        <color rgba="0.40 0.40 0.40 1" />
      </material>
    </visual>
  </link>
  <link name="l_middle2_link">
    <visual>
      <geometry>
        <mesh filename="package://inmoov_meshes/meshes/middle3_2.stl" scale="0.001 0.001 0.001" />
      </geometry>
      <origin rpy="0 0 0" xyz="0 0 0" />
      <material name="cframe">
        <color rgba="0.40 0.40 0.40 1" />
      </material>
    </visual>
  </link>
  <link name="l_middle3_link">
    <visual>
      <geometry>
        <mesh filename="package://inmoov_meshes/meshes/middle3_3.stl" scale="0.001 0.001 0.001" />
      </geometry>
      <origin rpy="0 0 0" xyz="0 0 0" />
      <material name="cframe">
        <color rgba="0.40 0.40 0.40 1" />
      </material>
    </visual>
  </link>
  <link name="l_ring1_link">
    <visual>
      <geometry>
        <mesh filename="package://inmoov_meshes/meshes/l_ring3_1.stl" scale="0.001 0.001 0.001" />
      </geometry>
      <origin rpy="0 0 0" xyz="0 0 0" />
      <material name="cframe">
        <color rgba="0.40 0.40 0.40 1" />
      </material>
    </visual>
  </link>
  <link name="l_ring2_link">
    <visual>
      <geometry>
        <mesh filename="package://inmoov_meshes/meshes/ring3_2.stl" scale="0.001 0.001 0.001" />
      </geometry>
      <origin rpy="0 0 0" xyz="0 0 0" />
      <material name="cframe">
        <color rgba="0.40 0.40 0.40 1" />
      </material>
    </visual>
  </link>
  <link name="l_ring3_link">
    <visual>
      <geometry>
        <mesh filename="package://inmoov_meshes/meshes/ring3_3.stl" scale="0.001 0.001 0.001" />
      </geometry>
      <origin rpy="0 0 0" xyz="0 0 0" />
      <material name="cframe">
        <color rgba="0.40 0.40 0.40 1" />
      </material>
    </visual>
  </link>
  <link name="l_ring4_link">
    <visual>
      <geometry>
        <mesh filename="package://inmoov_meshes/meshes/ring3_4.stl" scale="0.001 0.001 0.001" />
      </geometry>
      <origin rpy="0 0 0" xyz="0 0 0" />
      <material name="cframe">
        <color rgba="0.40 0.40 0.40 1" />
      </material>
    </visual>
  </link>
  <link name="l_pinky1_link">
    <visual>
      <geometry>
        <mesh filename="package://inmoov_meshes/meshes/l_pinky3_1.stl" scale="0.001 0.001 0.001" />
      </geometry>
      <origin rpy="0 0 0" xyz="0 0 0" />
      <material name="cframe">
        <color rgba="0.40 0.40 0.40 1" />
      </material>
    </visual>
  </link>
  <link name="l_pinky2_link">
    <visual>
      <geometry>
        <mesh filename="package://inmoov_meshes/meshes/pinky3_2.stl" scale="0.001 0.001 0.001" />
      </geometry>
      <origin rpy="0 0 0" xyz="0 0 0" />
      <material name="cframe">
        <color rgba="0.40 0.40 0.40 1" />
      </material>
    </visual>
  </link>
  <link name="l_pinky3_link">
    <visual>
      <geometry>
        <mesh filename="package://inmoov_meshes/meshes/pinky3_3.stl" scale="0.001 0.001 0.001" />
      </geometry>
      <origin rpy="0 0 0" xyz="0 0 0" />
      <material name="cframe">
        <color rgba="0.40 0.40 0.40 1" />
      </material>
    </visual>
  </link>
  <link name="l_pinky4_link">
    <visual>
      <geometry>
        <mesh filename="package://inmoov_meshes/meshes/pinky3_4.stl" scale="0.001 0.001 0.001" />
      </geometry>
      <origin rpy="0 0 0" xyz="0 0 0" />
      <material name="cframe">
        <color rgba="0.40 0.40 0.40 1" />
      </material>
    </visual>
  </link>
  <link name="l_gripper_link" />
  <joint name="l_gripper_joint" type="fixed">
    <origin rpy="1.57 0 3.14" xyz="-0.0127 0 -0.0762" />
    <parent link="l_hand_link" />
    <child link="l_gripper_link" />
  </joint>
  <joint name="l_thumb1_joint" type="revolute">
    <axis xyz="0 0 1" />
    <limit effort="1000.0" lower="0.0" upper="1.0471975512" velocity="0.0" />
    <origin rpy="-0.1 0 0" xyz="0 -0.029 -0.0577" />
    <mimic joint="l_thumb_joint" multiplier="-0.75" offset="0" />
    <parent link="l_hand_link" />
    <child link="l_thumb1_link" />
  </joint>
  <joint name="l_thumb_joint" type="revolute">
    <axis xyz="0 1 0" />
    <limit effort="1000.0" lower="0.0" upper="1.0471975512" velocity="0.0" />
    <origin rpy="-0.825 -0.1 -0.3" xyz="-0.00052 -0.02725  -0.013" />
    <parent link="l_thumb1_link" />
    <child link="l_thumb2_link" />
  </joint>
  <joint name="l_thumb3_joint" type="revolute">
    <axis xyz="0 1 0" />
    <limit effort="1000.0" lower="0.0" upper="1.0471975512" velocity="0.0" />
    <origin rpy="0 0 0" xyz="0 0 -0.035" />
    <mimic joint="l_thumb_joint" multiplier="1" offset="0" />
    <parent link="l_thumb2_link" />
    <child link="l_thumb3_link" />
  </joint>
  <joint name="l_index1_joint" type="revolute">
    <axis xyz="0 1 0" />
    <limit effort="1000.0" lower="0.0" upper="1.4835298642" velocity="0.0" />
    <origin rpy="-0.1 0 0" xyz="-0.0015 -0.0342  -0.119" />
    <mimic joint="l_index_joint" multiplier="1" offset="0" />
    <parent link="l_hand_link" />
    <child link="l_index1_link" />
  </joint>
  <joint name="l_index_joint" type="revolute">
    <axis xyz="0 1 0" />
    <limit effort="1000.0" lower="0.0" upper="1.4835298642" velocity="0.0" />
    <origin rpy="0 0 0" xyz="0 0.001 -0.03595" />
    <parent link="l_index1_link" />
    <child link="l_index2_link" />
  </joint>
  <joint name="l_index3_joint" type="revolute">
    <axis xyz="0 1 0" />
    <limit effort="1000.0" lower="0.0" upper="1.4835298642" velocity="0.0" />
    <origin rpy="0 0 0" xyz="0 0 -0.024" />
    <mimic joint="l_index_joint" multiplier="1" offset="0" />
    <parent link="l_index2_link" />
    <child link="l_index3_link" />
  </joint>
  <joint name="l_middle1_joint" type="revolute">
    <axis xyz="0 1 0" />
    <limit effort="1000.0" lower="0.0" upper="1.4835298642" velocity="0.0" />
    <origin rpy="0 0 0" xyz="-0.00175 -0.007  -0.12325" />
    <mimic joint="l_middle_joint" multiplier="1" offset="0" />
    <parent link="l_hand_link" />
    <child link="l_middle1_link" />
  </joint>
  <joint name="l_middle_joint" type="revolute">
    <axis xyz="0 1 0" />
    <limit effort="1000.0" lower="0.0" upper="1.4835298642" velocity="0.0" />
    <origin rpy="0 0 0" xyz="0 0.000 -0.0389" />
    <parent link="l_middle1_link" />
    <child link="l_middle2_link" />
  </joint>
  <joint name="l_middle3_joint" type="revolute">
    <axis xyz="0 1 0" />
    <limit effort="1000.0" lower="0.0" upper="1.4835298642" velocity="0.0" />
    <origin rpy="0 0 0" xyz="0 0.0005 -0.0259" />
    <mimic joint="l_middle_joint" multiplier="1" offset="0" />
    <parent link="l_middle2_link" />
    <child link="l_middle3_link" />
  </joint>
  <joint name="l_ring1_joint" type="revolute">
    <axis xyz="0 0 1" />
    <limit effort="1000.0" lower="0.0" upper="1.308996939" velocity="0.0" />
    <origin rpy="-0.7 0 0" xyz="0 0.00705 -0.0794" />
    <mimic joint="l_ring_joint" multiplier="0.1" offset="0" />
    <parent link="l_hand_link" />
    <child link="l_ring1_link" />
  </joint>
  <joint name="l_ring_joint" type="revolute">
    <axis xyz="0 1 0" />
    <limit effort="1000.0" lower="0.0" upper="1.308996939" velocity="0.0" />
    <origin rpy="0.7775 0 0" xyz="0.00126 0.0351 -0.0166" />
    <parent link="l_ring1_link" />
    <child link="l_ring2_link" />
  </joint>
  <joint name="l_ring3_joint" type="revolute">
    <axis xyz="0 1 0" />
    <limit effort="1000.0" lower="0.0" upper="1.308996939" velocity="0.0" />
    <origin rpy="0 0 0" xyz="0 0.0005 -0.0345" />
    <mimic joint="l_ring_joint" multiplier="1" offset="0" />
    <parent link="l_ring2_link" />
    <child link="l_ring3_link" />
  </joint>
  <joint name="l_ring4_joint" type="revolute">
    <axis xyz="0 1 0" />
    <limit effort="1000.0" lower="0.0" upper="1.308996939" velocity="0.0" />
    <origin rpy="0 0 0" xyz="0 0.0004 -0.0229" />
    <mimic joint="l_ring_joint" multiplier="1" offset="0" />
    <parent link="l_ring3_link" />
    <child link="l_ring4_link" />
  </joint>
  <joint name="l_pinky1_joint" type="revolute">
    <axis xyz="0 0 1" />
    <limit effort="1000.0" lower="0.0" upper="1.308996939" velocity="0.0" />
    <origin rpy="-0.7 0 0" xyz="0 0.027 -0.0555" />
    <mimic joint="l_pinky_joint" multiplier="0.1" offset="0" />
    <parent link="l_hand_link" />
    <child link="l_pinky1_link" />
  </joint>
  <joint name="l_pinky_joint" type="revolute">
    <axis xyz="0 1 0" />
    <limit effort="1000.0" lower="0.0" upper="1.308996939" velocity="0.0" />
    <origin rpy="0.93 0 0" xyz="0 0.046 -0.0228" />
    <parent link="l_pinky1_link" />
    <child link="l_pinky2_link" />
  </joint>
  <joint name="l_pinky3_joint" type="revolute">
    <axis xyz="0 1 0" />
    <limit effort="1000.0" lower="0.0" upper="1.308996939" velocity="0.0" />
    <origin rpy="0 0 0" xyz="0 0.0005 -0.031" />
    <mimic joint="l_pinky_joint" multiplier="1" offset="0" />
    <parent link="l_pinky2_link" />
    <child link="l_pinky3_link" />
  </joint>
  <joint name="l_pinky4_joint" type="revolute">
    <axis xyz="0 1 0" />
    <limit effort="1000.0" lower="0.0" upper="1.308996939" velocity="0.0" />
    <origin rpy="0 0 0" xyz="0 0.0004 -0.0208" />
    <mimic joint="l_pinky_joint" multiplier="1" offset="0" />
    <parent link="l_pinky3_link" />
    <child link="l_pinky4_link" />
  </joint>
  <link name="l_handcover_link">
    <visual>
      <geometry>
        <mesh filename="package://inmoov_meshes/meshes/l_cover_hand.stl" scale="0.001 0.001 0.001" />
      </geometry>
      <origin rpy="0 0 0" xyz="0 0 0" />
      <material name="ccover">
        <color rgba="0.75 0.75 0.75 1.0" />
      </material>
    </visual>
  </link>
  <link name="l_cover_handring_link">
    <visual>
      <geometry>
        <mesh filename="package://inmoov_meshes/meshes/l_cover_handring.stl" scale="0.001 0.001 0.001" />
      </geometry>
      <origin rpy="0 0 0" xyz="0 0 0" />
      <material name="ccover">
        <color rgba="0.75 0.75 0.75 1.0" />
      </material>
    </visual>
  </link>
  <link name="l_cover_handpinky_link">
    <visual>
      <geometry>
        <mesh filename="package://inmoov_meshes/meshes/l_cover_handpinky.stl" scale="0.001 0.001 0.001" />
      </geometry>
      <origin rpy="0 0 0" xyz="0 0 0" />
      <material name="ccover">
        <color rgba="0.75 0.75 0.75 1.0" />
      </material>
    </visual>
  </link>
  <link name="l_cover_thumb_link">
    <visual>
      <geometry>
        <mesh filename="package://inmoov_meshes/meshes/l_cover_thumb.stl" scale="0.001 0.001 0.001" />
      </geometry>
      <origin rpy="0 0 0" xyz="0 0 0" />
      <material name="ccover">
        <color rgba="0.75 0.75 0.75 1.0" />
      </material>
    </visual>
  </link>
  <link name="l_cover_index_link">
    <visual>
      <geometry>
        <mesh filename="package://inmoov_meshes/meshes/l_cover_index.stl" scale="0.001 0.001 0.001" />
      </geometry>
      <origin rpy="0 0 0" xyz="0 0 0" />
      <material name="ccover">
        <color rgba="0.75 0.75 0.75 1.0" />
      </material>
    </visual>
  </link>
  <link name="l_cover_middle_link">
    <visual>
      <geometry>
        <mesh filename="package://inmoov_meshes/meshes/l_cover_middle.stl" scale="0.001 0.001 0.001" />
      </geometry>
      <origin rpy="0 0 0" xyz="0 0 0" />
      <material name="ccover">
        <color rgba="0.75 0.75 0.75 1.0" />
      </material>
    </visual>
  </link>
  <link name="l_cover_ring_link">
    <visual>
      <geometry>
        <mesh filename="package://inmoov_meshes/meshes/l_cover_ring.stl" scale="0.001 0.001 0.001" />
      </geometry>
      <origin rpy="0 0 0" xyz="0 0 0" />
      <material name="ccover">
        <color rgba="0.75 0.75 0.75 1.0" />
      </material>
    </visual>
  </link>
  <link name="l_cover_pinky_link">
    <visual>
      <geometry>
        <mesh filename="package://inmoov_meshes/meshes/l_cover_pinky.stl" scale="0.001 0.001 0.001" />
      </geometry>
      <origin rpy="0 0 0" xyz="0 0 0" />
      <material name="ccover">
        <color rgba="0.75 0.75 0.75 1.0" />
      </material>
    </visual>
  </link>
  <joint name="l_handcover_joint" type="fixed">
    <origin rpy="0 0 0" xyz="0.009 -0.0192 -0.0977" />
    <parent link="l_hand_link" />
    <child link="l_handcover_link" />
  </joint>
  <joint name="l_cover_handpinky_joint" type="fixed">
    <origin rpy="0.7 0 0" xyz="0.01 0.02025 -0.0071" />
    <parent link="l_pinky1_link" />
    <child link="l_cover_handpinky_link" />
  </joint>
  <joint name="l_cover_handring_joint" type="fixed">
    <origin rpy="0.7 0 0" xyz="0.009 0.015 -0.0008" />
    <parent link="l_ring1_link" />
    <child link="l_cover_handring_link" />
  </joint>
  <joint name="l_cover_middle_joint" type="fixed">
    <origin rpy="0 0.05 0" xyz="0.0071 0 -0.012" />
    <parent link="l_middle1_link" />
    <child link="l_cover_middle_link" />
  </joint>
  <joint name="l_cover_thumb_joint" type="fixed">
    <origin rpy="-0.05 0 0" xyz="0.01 -0.02125 0.0047" />
    <parent link="l_thumb1_link" />
    <child link="l_cover_thumb_link" />
  </joint>
  <joint name="l_cover_index_joint" type="fixed">
    <origin rpy="0 -0.05 0" xyz="0.0071 0 -0.012" />
    <parent link="l_index1_link" />
    <child link="l_cover_index_link" />
  </joint>
  <joint name="l_cover_ring_joint" type="fixed">
    <origin rpy="-0.1 0.05 0" xyz="0.005 0 -0.011" />
    <parent link="l_ring2_link" />
    <child link="l_cover_ring_link" />
  </joint>
  <joint name="l_cover_pinky_joint" type="fixed">
    <origin rpy="-0.1 0.05 0" xyz="0.005 0 -0.0105" />
    <parent link="l_pinky2_link" />
    <child link="l_cover_pinky_link" />
  </joint>
  <joint name="l_wrist_roll_joint" type="revolute">
    <axis xyz="0 0 1" />
    <limit effort="1000.0" lower="2.12930168743" upper="3.83972435439" velocity="0.0" />
    <origin rpy="0 0 1.57" xyz="-0.0144 -0.01  -0.2885" />
    <parent link="l_forearm_link" />
    <child link="l_hand_link" />
  </joint>
</robot>
