<?xml version='1.0'?>

<robot name="inmoov_base" xmlns:xacro="http://www.ros.org/wiki/xacro">

  

  <xacro:include filename="$(find inmoov_description)/urdf/inmoov_base.gazebo" />
  <xacro:include filename="$(find inmoov_description)/urdf/materials.urdf.xacro" />
  <xacro:include filename="$(find inmoov_description)/urdf/inmoov_base_macros.xacro" />



  <link name='chassis'>
    <pose>0 0 0.1 0 0 0</pose>

    <inertial>
      <mass value="15.0"/>
      <origin xyz="0.0 0 0.1" rpy=" 0 0 0"/>
      <inertia
          ixx="0.1" ixy="0" ixz="0"
          iyy="0.1" iyz="0"
          izz="0.1"
      />
    </inertial>

    <collision name='collision'>
      <geometry>
        <box size=".5715 .371475 .127"/>
      </geometry>
    </collision>

    <visual name='chassis_visual'>
      <origin xyz="0 0 0" rpy=" 0 0 0"/>
      <geometry>
        <!--<box size=".5715 .371475 .127"/>-->
        <mesh filename="package://inmoov_meshes/meshes/base.stl" scale="0.001 0.001 0.001"/>
      </geometry>
      
    </visual>


    <collision name='caster_collision'>
      <origin xyz="-.28575 0 -0.0889" rpy=" 0 0 0"/>
      <geometry>
        <sphere radius="0.0889"/>
      </geometry>
      <surface>
        <friction>
          <ode>
            <mu>0</mu>
            <mu2>0</mu2>
            <slip1>1.0</slip1>
            <slip2>1.0</slip2>
          </ode>
        </friction>
      </surface>
    </collision>

    <visual name='caster_visual'>
      <origin xyz="-.28575 0 -0.0889" rpy=" 0 0 0"/>
      <geometry>
        <sphere radius="0.0889"/>
      </geometry>
    </visual>


   <!-- <collision name='caster_back_collision'>
      <origin xyz="-.28575 0 -0.0889" rpy=" 0 1.5707 1.5707"/>
      <geometry>
        <cylinder radius="0.0889" length="0.0254"/>
      </geometry>
      <surface>
        <friction>
          <ode>
            <mu>0</mu>
            <mu2>0</mu2>
            <slip1>1.0</slip1>
            <slip2>1.0</slip2>
          </ode>
        </friction>
      </surface>
    </collision>

    <visual name='caster_back_visual'>
      <origin xyz="-.28575 0 -0.0889" rpy=" 0 1.5707 1.5707"/>
      <geometry>
        <cylinder radius="0.0889" length="0.0254"/>
      </geometry>
    </visual> -->


  </link>


  <link name="left_wheel">
    <!--origin xyz="0.1 0.13 0.1" rpy="0 1.5707 1.5707"/-->
    <collision name="collision">
      <origin xyz="0 0 0" rpy="0 1.5707 1.5707"/>
      <geometry>
        <cylinder radius="0.2032" length="0.0381"/>
      </geometry>
    </collision>
    <visual name="left_wheel_visual">
      <origin xyz="0 0 0" rpy="0 1.5707 1.5707"/>
      <geometry>
        <cylinder radius="0.2032" length="0.0381"/>
      </geometry>
    </visual>
    <inertial>
      <origin xyz="0 0 0" rpy="0 1.5707 1.5707"/>
      <mass value="5"/>
      <inertia
        ixx=".1" ixy="0.0" ixz="0.0"
        iyy=".1" iyz="0.0"
        izz=".1"/>
    </inertial>
  </link>

  <link name="right_wheel">
    <!--origin xyz="0.1 -0.13 0.1" rpy="0 1.5707 1.5707"/-->
    <collision name="collision">
      <origin xyz="0 0 0" rpy="0 1.5707 1.5707"/>
      <geometry>
        <cylinder radius="0.2032" length="0.0381"/>
      </geometry>
    </collision>
    <visual name="right_wheel_visual">
      <origin xyz="0 0 0" rpy="0 1.5707 1.5707"/>
      <geometry>
        <cylinder radius="0.2032" length="0.0381"/>
      </geometry>
    </visual>
    <inertial>
      <origin xyz="0 0 0" rpy="0 1.5707 1.5707"/>
      <mass value="5"/>
      <inertia
        ixx=".1" ixy="0.0" ixz="0.0"
        iyy=".1" iyz="0.0"
        izz=".1"/>
    </inertial>
  </link>


  <joint type="continuous" name="left_wheel_hinge">
    <origin xyz=".28575 0.2047875 0" rpy="0 0 0"/>
    <!--origin xyz="0.1 0.13 0" rpy="0 1.5707 1.5707"/-->
    <child link="left_wheel"/>
    <parent link="chassis"/>
    <axis xyz="0 1 0" rpy="0 0 0"/>
    <limit effort="10000" velocity="1000"/>
    <joint_properties damping="1.0" friction="1.0"/>
  </joint>

  <joint type="continuous" name="right_wheel_hinge">
    <origin xyz=".28575 -0.2047875 0" rpy="0 0 0"/>
    <!--origin xyz="0.1 -0.13 0" rpy="0 1.5707 1.5707"/-->
    <child link="right_wheel"/>
    <parent link="chassis"/>
    <axis xyz="0 1 0" rpy="0 0 0"/>
    <limit effort="100" velocity="100"/>
    <joint_properties damping="1.0" friction="1.0"/>
  </joint>


  

 

</robot>
