<?xml version="1.0" ?>
<!-- =================================================================================== -->
<!-- |    This document was autogenerated by xacro from inmoov_l_arm.urdf.xacro        | -->
<!-- |    EDITING THIS FILE BY HAND IS NOT RECOMMENDED                                 | -->
<!-- =================================================================================== -->
<robot name="inmoov" xmlns:xacro="http://ros.org/wiki/xacro">
  <!--xacro:property name="pi" value="3.1415926539"/-->
  <!--xacro:property name="pi" value="3.1415926539"/-->
  <link name="torso_link">
    <visual>
      <geometry>
        <mesh filename="package://inmoov_meshes/meshes/torso.stl" scale="0.001 0.001 0.001"/>
      </geometry>
      <origin rpy="0 0 0" xyz="0 0 0"/>
      <material name="cframe">
        <color rgba="0.40 0.40 0.40 1"/>
      </material>
    </visual>
  </link>
  <link name="l_shoulder_base_link">
    <visual>
      <geometry>
        <mesh filename="package://inmoov_meshes/meshes/l_shoulder_base.stl" scale="0.001 0.001 0.001"/>
      </geometry>
      <origin rpy="0 0 0" xyz="0 0 0"/>
      <material name="cframe">
        <color rgba="0.40 0.40 0.40 1"/>
      </material>
    </visual>
  </link>
  <link name="l_shoulder_link">
    <visual>
      <geometry>
        <mesh filename="package://inmoov_meshes/meshes/l_shoulder.stl" scale="0.001 0.001 0.001"/>
      </geometry>
      <origin rpy="0 0 0" xyz="0 0 0"/>
      <material name="cframe">
        <color rgba="0.40 0.40 0.40 1"/>
      </material>
    </visual>
  </link>
  <link name="l_bicep_link">
    <visual>
      <geometry>
        <mesh filename="package://inmoov_meshes/meshes/bicep.stl" scale="0.001 0.001 0.001"/>
      </geometry>
      <origin rpy="0 0 0" xyz="0 0 0"/>
      <material name="cframe">
        <color rgba="0.40 0.40 0.40 1"/>
      </material>
    </visual>
  </link>
  <link name="l_bicepcover_link">
    <visual>
      <geometry>
        <mesh filename="package://inmoov_meshes/meshes/bicepcover.stl" scale="0.001 0.001 0.001"/>
      </geometry>
      <origin rpy="0 0 0" xyz="0 0 0"/>
      <material name="ccover">
        <color rgba="0.75 0.75 0.75 1.0"/>
      </material>
    </visual>
  </link>
  <link name="l_forearm_link">
    <visual>
      <geometry>
        <mesh filename="package://inmoov_meshes/meshes/l_forearm.stl" scale="0.001 0.001 0.001"/>
      </geometry>
      <origin rpy="0 0 0" xyz="-0.001 0 0"/>
      <material name="ccover">
        <color rgba="0.75 0.75 0.75 1.0"/>
      </material>
    </visual>
  </link>
  <joint name="l_shoulder_lift_joint" type="revolute">
    <axis xyz="0 1 0"/>
    <limit effort="1000.0" lower="-3.14159265359" upper="0.541052068118" velocity="0.0"/>
    <origin rpy="0 0 0" xyz="0 0.012 -0.04"/>
    <parent link="l_shoulder_base_link"/>
    <child link="l_shoulder_link"/>
  </joint>
  <joint name="l_upper_arm_roll_joint" type="revolute">
    <axis xyz="0 0 1"/>
    <limit effort="1000.0" lower="-1.53588974176" upper="1.44862327916" velocity="0.0"/>
    <origin rpy="0 0 0" xyz="0 0.066 -0.060"/>
    <parent link="l_shoulder_link"/>
    <child link="l_bicep_link"/>
  </joint>
  <joint name="l_elbow_flex_joint" type="revolute">
    <axis xyz="0 1 0"/>
    <limit effort="1000.0" lower="-1.4835298642" upper="-0.383972435439" velocity="0.0"/>
    <origin rpy="0 0 0" xyz="-0.0278 0 -0.2235"/>
    <parent link="l_bicep_link"/>
    <child link="l_forearm_link"/>
  </joint>
  <joint name="l_bicepcover_joint" type="fixed">
    <origin rpy="0 0 0" xyz="0 0 0"/>
    <parent link="l_bicep_link"/>
    <child link="l_bicepcover_link"/>
  </joint>
  <joint name="l_shoulder_out_joint" type="revolute">
    <axis xyz="1 0 0"/>
    <limit effort="1000.0" lower="0.0872664625997" upper="1.27409035396" velocity="0.0"/>
    <origin rpy="0 0 0" xyz="0 0.143 0.298"/>
    <parent link="torso_link"/>
    <child link="l_shoulder_base_link"/>
  </joint>
  <link name="l_hand_link">
    <visual>
      <geometry>
        <mesh filename="package://inmoov_meshes/meshes/l_hand.stl" scale="0.001 0.001 0.001"/>
      </geometry>
      <origin rpy="0 0 0" xyz="0 0 0"/>
      <material name="cframe">
        <color rgba="0.40 0.40 0.40 1"/>
      </material>
    </visual>
  </link>
  <link name="l_thumb1_link">
    <visual>
      <geometry>
        <mesh filename="package://inmoov_meshes/meshes/l_thumb5_1.stl" scale="0.001 0.001 0.001"/>
      </geometry>
      <origin rpy="0 0 0" xyz="0 0 0"/>
      <material name="cframe">
        <color rgba="0.40 0.40 0.40 1"/>
      </material>
    </visual>
  </link>
  <link name="l_thumb2_link">
    <visual>
      <geometry>
        <mesh filename="package://inmoov_meshes/meshes/thumb5_2.stl" scale="0.001 0.001 0.001"/>
      </geometry>
      <origin rpy="0 0 0" xyz="0 0 0"/>
      <material name="cframe">
        <color rgba="0.40 0.40 0.40 1"/>
      </material>
    </visual>
  </link>
  <link name="l_thumb3_link">
    <visual>
      <geometry>
        <mesh filename="package://inmoov_meshes/meshes/thumb5_3.stl" scale="0.001 0.001 0.001"/>
      </geometry>
      <origin rpy="0 0 0" xyz="0 0 0"/>
      <material name="cframe">
        <color rgba="0.40 0.40 0.40 1"/>
      </material>
    </visual>
  </link>
  <link name="l_index1_link">
    <visual>
      <geometry>
        <mesh filename="package://inmoov_meshes/meshes/index3_1.stl" scale="0.001 0.001 0.001"/>
      </geometry>
      <origin rpy="0 0 0" xyz="0 0 0"/>
      <material name="cframe">
        <color rgba="0.40 0.40 0.40 1"/>
      </material>
    </visual>
  </link>
  <link name="l_index2_link">
    <visual>
      <geometry>
        <mesh filename="package://inmoov_meshes/meshes/index3_2.stl" scale="0.001 0.001 0.001"/>
      </geometry>
      <origin rpy="0 0 0" xyz="0 0 0"/>
      <material name="cframe">
        <color rgba="0.40 0.40 0.40 1"/>
      </material>
    </visual>
  </link>
  <link name="l_index3_link">
    <visual>
      <geometry>
        <mesh filename="package://inmoov_meshes/meshes/index3_3.stl" scale="0.001 0.001 0.001"/>
      </geometry>
      <origin rpy="0 0 0" xyz="0 0 0"/>
      <material name="cframe">
        <color rgba="0.40 0.40 0.40 1"/>
      </material>
    </visual>
  </link>
  <link name="l_middle1_link">
    <visual>
      <geometry>
        <mesh filename="package://inmoov_meshes/meshes/middle3_1.stl" scale="0.001 0.001 0.001"/>
      </geometry>
      <origin rpy="0 0 0" xyz="0 0 0"/>
      <material name="cframe">
        <color rgba="0.40 0.40 0.40 1"/>
      </material>
    </visual>
  </link>
  <link name="l_middle2_link">
    <visual>
      <geometry>
        <mesh filename="package://inmoov_meshes/meshes/middle3_2.stl" scale="0.001 0.001 0.001"/>
      </geometry>
      <origin rpy="0 0 0" xyz="0 0 0"/>
      <material name="cframe">
        <color rgba="0.40 0.40 0.40 1"/>
      </material>
    </visual>
  </link>
  <link name="l_middle3_link">
    <visual>
      <geometry>
        <mesh filename="package://inmoov_meshes/meshes/middle3_3.stl" scale="0.001 0.001 0.001"/>
      </geometry>
      <origin rpy="0 0 0" xyz="0 0 0"/>
      <material name="cframe">
        <color rgba="0.40 0.40 0.40 1"/>
      </material>
    </visual>
  </link>
  <link name="l_ring1_link">
    <visual>
      <geometry>
        <mesh filename="package://inmoov_meshes/meshes/l_ring3_1.stl" scale="0.001 0.001 0.001"/>
      </geometry>
      <origin rpy="0 0 0" xyz="0 0 0"/>
      <material name="cframe">
        <color rgba="0.40 0.40 0.40 1"/>
      </material>
    </visual>
  </link>
  <link name="l_ring2_link">
    <visual>
      <geometry>
        <mesh filename="package://inmoov_meshes/meshes/ring3_2.stl" scale="0.001 0.001 0.001"/>
      </geometry>
      <origin rpy="0 0 0" xyz="0 0 0"/>
      <material name="cframe">
        <color rgba="0.40 0.40 0.40 1"/>
      </material>
    </visual>
  </link>
  <link name="l_ring3_link">
    <visual>
      <geometry>
        <mesh filename="package://inmoov_meshes/meshes/ring3_3.stl" scale="0.001 0.001 0.001"/>
      </geometry>
      <origin rpy="0 0 0" xyz="0 0 0"/>
      <material name="cframe">
        <color rgba="0.40 0.40 0.40 1"/>
      </material>
    </visual>
  </link>
  <link name="l_ring4_link">
    <visual>
      <geometry>
        <mesh filename="package://inmoov_meshes/meshes/ring3_4.stl" scale="0.001 0.001 0.001"/>
      </geometry>
      <origin rpy="0 0 0" xyz="0 0 0"/>
      <material name="cframe">
        <color rgba="0.40 0.40 0.40 1"/>
      </material>
    </visual>
  </link>
  <link name="l_pinky1_link">
    <visual>
      <geometry>
        <mesh filename="package://inmoov_meshes/meshes/l_pinky3_1.stl" scale="0.001 0.001 0.001"/>
      </geometry>
      <origin rpy="0 0 0" xyz="0 0 0"/>
      <material name="cframe">
        <color rgba="0.40 0.40 0.40 1"/>
      </material>
    </visual>
  </link>
  <link name="l_pinky2_link">
    <visual>
      <geometry>
        <mesh filename="package://inmoov_meshes/meshes/pinky3_2.stl" scale="0.001 0.001 0.001"/>
      </geometry>
      <origin rpy="0 0 0" xyz="0 0 0"/>
      <material name="cframe">
        <color rgba="0.40 0.40 0.40 1"/>
      </material>
    </visual>
  </link>
  <link name="l_pinky3_link">
    <visual>
      <geometry>
        <mesh filename="package://inmoov_meshes/meshes/pinky3_3.stl" scale="0.001 0.001 0.001"/>
      </geometry>
      <origin rpy="0 0 0" xyz="0 0 0"/>
      <material name="cframe">
        <color rgba="0.40 0.40 0.40 1"/>
      </material>
    </visual>
  </link>
  <link name="l_pinky4_link">
    <visual>
      <geometry>
        <mesh filename="package://inmoov_meshes/meshes/pinky3_4.stl" scale="0.001 0.001 0.001"/>
      </geometry>
      <origin rpy="0 0 0" xyz="0 0 0"/>
      <material name="cframe">
        <color rgba="0.40 0.40 0.40 1"/>
      </material>
    </visual>
  </link>
  <joint name="l_thumb1_joint" type="revolute">
    <axis xyz="0 0 1"/>
    <limit effort="1000.0" lower="0.0" upper="1.0471975512" velocity="0.0"/>
    <origin rpy="-0.1 0 0" xyz="0 -0.029 -0.0577"/>
    <mimic joint="l_thumb_joint" multiplier="-0.75" offset="0"/>
    <parent link="l_hand_link"/>
    <child link="l_thumb1_link"/>
  </joint>
  <joint name="l_thumb_joint" type="revolute">
    <axis xyz="0 1 0"/>
    <limit effort="1000.0" lower="0.0" upper="1.0471975512" velocity="0.0"/>
    <origin rpy="-0.825 -0.1 -0.3" xyz="-0.00052 -0.02725  -0.013"/>
    <parent link="l_thumb1_link"/>
    <child link="l_thumb2_link"/>
  </joint>
  <joint name="l_thumb3_joint" type="revolute">
    <axis xyz="0 1 0"/>
    <limit effort="1000.0" lower="0.0" upper="1.0471975512" velocity="0.0"/>
    <origin rpy="0 0 0" xyz="0 0 -0.035"/>
    <mimic joint="l_thumb_joint" multiplier="1" offset="0"/>
    <parent link="l_thumb2_link"/>
    <child link="l_thumb3_link"/>
  </joint>
  <joint name="l_index1_joint" type="revolute">
    <axis xyz="0 1 0"/>
    <limit effort="1000.0" lower="0.0" upper="1.4835298642" velocity="0.0"/>
    <origin rpy="-0.1 0 0" xyz="-0.0015 -0.0342  -0.119"/>
    <mimic joint="l_index_joint" multiplier="1" offset="0"/>
    <parent link="l_hand_link"/>
    <child link="l_index1_link"/>
  </joint>
  <joint name="l_index_joint" type="revolute">
    <axis xyz="0 1 0"/>
    <limit effort="1000.0" lower="0.0" upper="1.4835298642" velocity="0.0"/>
    <origin rpy="0 0 0" xyz="0 0.001 -0.03595"/>
    <parent link="l_index1_link"/>
    <child link="l_index2_link"/>
  </joint>
  <joint name="l_index3_joint" type="revolute">
    <axis xyz="0 1 0"/>
    <limit effort="1000.0" lower="0.0" upper="1.4835298642" velocity="0.0"/>
    <origin rpy="0 0 0" xyz="0 0 -0.024"/>
    <mimic joint="l_index_joint" multiplier="1" offset="0"/>
    <parent link="l_index2_link"/>
    <child link="l_index3_link"/>
  </joint>
  <joint name="l_middle1_joint" type="revolute">
    <axis xyz="0 1 0"/>
    <limit effort="1000.0" lower="0.0" upper="1.4835298642" velocity="0.0"/>
    <origin rpy="0 0 0" xyz="-0.00175 -0.007  -0.12325"/>
    <mimic joint="l_middle_joint" multiplier="1" offset="0"/>
    <parent link="l_hand_link"/>
    <child link="l_middle1_link"/>
  </joint>
  <joint name="l_middle_joint" type="revolute">
    <axis xyz="0 1 0"/>
    <limit effort="1000.0" lower="0.0" upper="1.4835298642" velocity="0.0"/>
    <origin rpy="0 0 0" xyz="0 0.000 -0.0389"/>
    <parent link="l_middle1_link"/>
    <child link="l_middle2_link"/>
  </joint>
  <joint name="l_middle3_joint" type="revolute">
    <axis xyz="0 1 0"/>
    <limit effort="1000.0" lower="0.0" upper="1.4835298642" velocity="0.0"/>
    <origin rpy="0 0 0" xyz="0 0.0005 -0.0259"/>
    <mimic joint="l_middle_joint" multiplier="1" offset="0"/>
    <parent link="l_middle2_link"/>
    <child link="l_middle3_link"/>
  </joint>
  <joint name="l_ring1_joint" type="revolute">
    <axis xyz="0 0 1"/>
    <limit effort="1000.0" lower="0.0" upper="1.308996939" velocity="0.0"/>
    <origin rpy="-0.7 0 0" xyz="0 0.00705 -0.0794"/>
    <mimic joint="l_ring_joint" multiplier="0.1" offset="0"/>
    <parent link="l_hand_link"/>
    <child link="l_ring1_link"/>
  </joint>
  <joint name="l_ring_joint" type="revolute">
    <axis xyz="0 1 0"/>
    <limit effort="1000.0" lower="0.0" upper="1.308996939" velocity="0.0"/>
    <origin rpy="0.7775 0 0" xyz="0.00126 0.0351 -0.0166"/>
    <parent link="l_ring1_link"/>
    <child link="l_ring2_link"/>
  </joint>
  <joint name="l_ring3_joint" type="revolute">
    <axis xyz="0 1 0"/>
    <limit effort="1000.0" lower="0.0" upper="1.308996939" velocity="0.0"/>
    <origin rpy="0 0 0" xyz="0 0.0005 -0.0345"/>
    <mimic joint="l_ring_joint" multiplier="1" offset="0"/>
    <parent link="l_ring2_link"/>
    <child link="l_ring3_link"/>
  </joint>
  <joint name="l_ring4_joint" type="revolute">
    <axis xyz="0 1 0"/>
    <limit effort="1000.0" lower="0.0" upper="1.308996939" velocity="0.0"/>
    <origin rpy="0 0 0" xyz="0 0.0004 -0.0229"/>
    <mimic joint="l_ring_joint" multiplier="1" offset="0"/>
    <parent link="l_ring3_link"/>
    <child link="l_ring4_link"/>
  </joint>
  <joint name="l_pinky1_joint" type="revolute">
    <axis xyz="0 0 1"/>
    <limit effort="1000.0" lower="0.0" upper="1.308996939" velocity="0.0"/>
    <origin rpy="-0.7 0 0" xyz="0 0.027 -0.0555"/>
    <mimic joint="l_pinky_joint" multiplier="0.1" offset="0"/>
    <parent link="l_hand_link"/>
    <child link="l_pinky1_link"/>
  </joint>
  <joint name="l_pinky_joint" type="revolute">
    <axis xyz="0 1 0"/>
    <limit effort="1000.0" lower="0.0" upper="1.308996939" velocity="0.0"/>
    <origin rpy="0.93 0 0" xyz="0 0.046 -0.0228"/>
    <parent link="l_pinky1_link"/>
    <child link="l_pinky2_link"/>
  </joint>
  <joint name="l_pinky3_joint" type="revolute">
    <axis xyz="0 1 0"/>
    <limit effort="1000.0" lower="0.0" upper="1.308996939" velocity="0.0"/>
    <origin rpy="0 0 0" xyz="0 0.0005 -0.031"/>
    <mimic joint="l_pinky_joint" multiplier="1" offset="0"/>
    <parent link="l_pinky2_link"/>
    <child link="l_pinky3_link"/>
  </joint>
  <joint name="l_pinky4_joint" type="revolute">
    <axis xyz="0 1 0"/>
    <limit effort="1000.0" lower="0.0" upper="1.308996939" velocity="0.0"/>
    <origin rpy="0 0 0" xyz="0 0.0004 -0.0208"/>
    <mimic joint="l_pinky_joint" multiplier="1" offset="0"/>
    <parent link="l_pinky3_link"/>
    <child link="l_pinky4_link"/>
  </joint>
  <link name="l_handcover_link">
    <visual>
      <geometry>
        <mesh filename="package://inmoov_meshes/meshes/l_cover_hand.stl" scale="0.001 0.001 0.001"/>
      </geometry>
      <origin rpy="0 0 0" xyz="0 0 0"/>
      <material name="ccover">
        <color rgba="0.75 0.75 0.75 1.0"/>
      </material>
    </visual>
  </link>
  <link name="l_cover_handring_link">
    <visual>
      <geometry>
        <mesh filename="package://inmoov_meshes/meshes/l_cover_handring.stl" scale="0.001 0.001 0.001"/>
      </geometry>
      <origin rpy="0 0 0" xyz="0 0 0"/>
      <material name="ccover">
        <color rgba="0.75 0.75 0.75 1.0"/>
      </material>
    </visual>
  </link>
  <link name="l_cover_handpinky_link">
    <visual>
      <geometry>
        <mesh filename="package://inmoov_meshes/meshes/l_cover_handpinky.stl" scale="0.001 0.001 0.001"/>
      </geometry>
      <origin rpy="0 0 0" xyz="0 0 0"/>
      <material name="ccover">
        <color rgba="0.75 0.75 0.75 1.0"/>
      </material>
    </visual>
  </link>
  <link name="l_cover_thumb_link">
    <visual>
      <geometry>
        <mesh filename="package://inmoov_meshes/meshes/l_cover_thumb.stl" scale="0.001 0.001 0.001"/>
      </geometry>
      <origin rpy="0 0 0" xyz="0 0 0"/>
      <material name="ccover">
        <color rgba="0.75 0.75 0.75 1.0"/>
      </material>
    </visual>
  </link>
  <link name="l_cover_index_link">
    <visual>
      <geometry>
        <mesh filename="package://inmoov_meshes/meshes/l_cover_index.stl" scale="0.001 0.001 0.001"/>
      </geometry>
      <origin rpy="0 0 0" xyz="0 0 0"/>
      <material name="ccover">
        <color rgba="0.75 0.75 0.75 1.0"/>
      </material>
    </visual>
  </link>
  <link name="l_cover_middle_link">
    <visual>
      <geometry>
        <mesh filename="package://inmoov_meshes/meshes/l_cover_middle.stl" scale="0.001 0.001 0.001"/>
      </geometry>
      <origin rpy="0 0 0" xyz="0 0 0"/>
      <material name="ccover">
        <color rgba="0.75 0.75 0.75 1.0"/>
      </material>
    </visual>
  </link>
  <link name="l_cover_ring_link">
    <visual>
      <geometry>
        <mesh filename="package://inmoov_meshes/meshes/l_cover_ring.stl" scale="0.001 0.001 0.001"/>
      </geometry>
      <origin rpy="0 0 0" xyz="0 0 0"/>
      <material name="ccover">
        <color rgba="0.75 0.75 0.75 1.0"/>
      </material>
    </visual>
  </link>
  <link name="l_cover_pinky_link">
    <visual>
      <geometry>
        <mesh filename="package://inmoov_meshes/meshes/l_cover_pinky.stl" scale="0.001 0.001 0.001"/>
      </geometry>
      <origin rpy="0 0 0" xyz="0 0 0"/>
      <material name="ccover">
        <color rgba="0.75 0.75 0.75 1.0"/>
      </material>
    </visual>
  </link>
  <joint name="l_handcover_joint" type="fixed">
    <origin rpy="0 0 0" xyz="0.009 -0.0192 -0.0977"/>
    <parent link="l_hand_link"/>
    <child link="l_handcover_link"/>
  </joint>
  <joint name="l_cover_handpinky_joint" type="fixed">
    <origin rpy="0.7 0 0" xyz="0.01 0.02025 -0.0071"/>
    <parent link="l_pinky1_link"/>
    <child link="l_cover_handpinky_link"/>
  </joint>
  <joint name="l_cover_handring_joint" type="fixed">
    <origin rpy="0.7 0 0" xyz="0.009 0.015 -0.0008"/>
    <parent link="l_ring1_link"/>
    <child link="l_cover_handring_link"/>
  </joint>
  <joint name="l_cover_middle_joint" type="fixed">
    <origin rpy="0 0.05 0" xyz="0.0071 0 -0.012"/>
    <parent link="l_middle1_link"/>
    <child link="l_cover_middle_link"/>
  </joint>
  <joint name="l_cover_thumb_joint" type="fixed">
    <origin rpy="-0.05 0 0" xyz="0.01 -0.02125 0.0047"/>
    <parent link="l_thumb1_link"/>
    <child link="l_cover_thumb_link"/>
  </joint>
  <joint name="l_cover_index_joint" type="fixed">
    <origin rpy="0 -0.05 0" xyz="0.0071 0 -0.012"/>
    <parent link="l_index1_link"/>
    <child link="l_cover_index_link"/>
  </joint>
  <joint name="l_cover_ring_joint" type="fixed">
    <origin rpy="-0.1 0.05 0" xyz="0.005 0 -0.011"/>
    <parent link="l_ring2_link"/>
    <child link="l_cover_ring_link"/>
  </joint>
  <joint name="l_cover_pinky_joint" type="fixed">
    <origin rpy="-0.1 0.05 0" xyz="0.005 0 -0.0105"/>
    <parent link="l_pinky2_link"/>
    <child link="l_cover_pinky_link"/>
  </joint>
  <joint name="l_wrist_roll_joint" type="revolute">
    <axis xyz="0 0 1"/>
    <limit effort="1000.0" lower="2.12930168743" upper="3.83972435439" velocity="0.0"/>
    <origin rpy="0 0 0" xyz="-0.0144 -0.01  -0.2885"/>
    <parent link="l_forearm_link"/>
    <child link="l_hand_link"/>
  </joint>
</robot>
